<mujoco model='basic move'>
    <!-- This file is going to make the structure of a moving_hand -->
	<compiler inertiafromgeom='true' angle='degree'/>
    <default>
        <joint limited='true' damping='1' armature='0'/>
        <geom contype='1' conaffinity='1' condim='1' rgba='0.5 0.3 .4 1'
        	margin="0.001" solref=".02 1" solimp=".8 .8 .01"/>
        <motor ctrlrange='-.4 .4' ctrllimited='true'/>
		<!-- add some classes -->
    </default>

    <option timestep='0.002' iterations="50" tolerance="1e-10" solver="Newton" jacobian="dense" cone="elliptic"/>

    <size nstack="1000000"/>

    <visual>
	<!-- the visual part, which is not very important -->
        <map fogstart="3" fogend="5" force="0.1" znear="0.5"/>
        <quality shadowsize="2048" offsamples="8"/>
        <global offwidth="800" offheight="800"/>
		<!-- the size of the scenary -->
    </visual>

    <asset>
        <!-- asset is the predefined setting -->
		<texture type="skybox" builtin="gradient" width="128" height="128" rgb1=".4 .6 .8" 
            rgb2="0 0 0"/>  
        <texture name="texgeom" type="cube" builtin="flat" mark="cross" width="127" height="1278" 
            rgb1="0.4 0.4 0.1" rgb2="0.5 0.5 0.1" markrgb="1 1 1" random="0.01"/>  
        <texture name="texplane" type="2d" builtin="checker" rgb1=".2 .3 .4" rgb2=".1 0.15 0.2" 
            width="512" height="512"/>  
		<!-- the material is a more complicated structure -->
        <material name='MatPlane' reflectance='0.3' texture="texplane" texrepeat="1 1" texuniform="true"/>
    </asset>

    <worldbody>
		<!-- the light is bounded on a body-->
        <light mode='targetbodycom' target='ball' directional='false' castshadow='false'  diffuse='.8 .8 .8' specular='0.3 0.3 0.3' pos='1 1 4.0' dir='0 0 -1'/>
		<!-- structure for the hand first -->
		<body name='ball' pos='-0.3 -0.3 0.0'>
            <!-- transition free on this plane -->
			<joint name='slide1' type='slide' range='0 1.0' axis='1 0 0' />
			<joint name='slide2' type='slide' range='0 1.0' axis='0 1 0' />
			<geom type='sphere' size="0.04" rgba=".5 .0 .5 1"/>
		</body>	
		<body name='slidebar' pos='0.3 0.3 0'>
			<geom type='sphere' size='0.05' rgba=".5 .5 .0 1"/>
			<site name='button' type='sphere' size='0.1' rgba='1 1 1 0'/>
			<!-- the button should free move -->
			<joint name='slide3' type='slide' range='0 1.0' axis='1 0 0' />
			<joint name='slide4' type='slide' range='0 1.0' axis='0 1 0' />
		</body>
		<!-- safety part ------------------------------------>
		<body name = 'irl' axisangle='0 0 1 -45' pos='0 0 0'>
		    <geom name = 'irl' pos='0 0 0' type='sphere' rgba='1 1 1 1' size = '0.1'/>
		    <site name='irl' pos='0 0 0' type='sphere' rgba='1 1 1 0' size='0.15'/>
            <joint name='irl' type='slide' range='-0.1 0.1' axis='1 0 0'/>
        </body>
		<!-- a coordinate around coordinate of size 0.15 -->
		<body name='door' axisangle='0 0 1 45' pos='0.2 0.2 0.05'>
			<geom type='box' size='0.02 0.5 0.05' rgba='1 1 1 1'/>
            <site name='door' type='box' size='0.025 0.55 0.1' rgba='0.5 0.5 0.5 1'/>
			<joint name='door' type='slide' range='0 1.0' axis='0 1 0' />
		</body>

        <camera name="camera1" mode="fixed" pos="0 0 2.6" /> 
        <camera name="camera2" mode="fixed" pos="0 0.5 0" quat="0 0 1 1"/>
    </worldbody>
	<!-- body finished -->
	<sensor>
		<touch name='touch_button' site='button'/>
		<touch name='door' site='door'/>
	</sensor>
	<!-- actuator -->
	<actuator>
		<motor joint='slide1' name='slide1' ctrlrange='-0.9 0.9'/>
		<motor joint='slide2' name='slide2' ctrlrange='-0.9 0.9'/>
		<motor joint='irl' name='irl' ctrlrange='-3 3'/>
		<motor joint='door' name='door' ctrlrange='-5.0 5.0'/>
	</actuator>
</mujoco>
